Workbook

Sheet RESUMO1
A1: TOTAL APLICADO
B2: 45658 | C2: 45689 | D2: 45717 | E2: 45748 | F2: 45778 | G2: 45809 | H2: 45839 | I2: 45870 | J2: 45901 | K2: 45931 | L2: 45962 | M2: 45992
B3: =SUM(B17,B34,B41,B47,B57) -> 20969398 | C3: =SUM(C17,C34,C41,C47,C57) -> 20835815 | D3: =SUM(D17,D34,D41,D47,D57) -> 20668068 | E3: =SUM(E17,E34,E41,E47,E57) -> 20668068 | F3: =SUM(F17,F34,F41,F47,F57) -> 20668068 | G3: =SUM(G17,G34,G41,G47,G57) -> 20668068 | H3: =SUM(H17,H34,H41,H47,H57) -> 20668068 | I3: =SUM(I17,I34,I41,I47,I57) -> 20668068 | ... M3: =SUM(M17,M34,M41,M47,M57) -> 20668068
A5: RENDIMENTOS
B6: 45658 | C6: 45689 | D6: 45717 | E6: 45748 | F6: 45778 | G6: 45809 | H6: 45839 | I6: 45870 | J6: 45901 | K6: 45931 | L6: 45962 | M6: 45992
B7: ='BANCO XP RENATA'!F10+'BANCO ITAÚ RENATA HELIO'!F17+SICOOB!F7+SAFRA!F7+SANTANDER!F12 -> 270984.87 | C7: =SUM('BANCO XP RENATA'!F19+'BANCO ITAÚ RENATA HELIO'!F33+SICOOB!F13+SAFRA!F13+SANTANDER!F22) -> 160291.18 | D7: =SUM('BANCO XP RENATA'!F28+'BANCO ITAÚ RENATA HELIO'!F49+SICOOB!F19+SAFRA!F19+SANTANDER!F32) -> 0 | E7: =SUM('BANCO XP RENATA'!F37+'BANCO ITAÚ RENATA HELIO'!F65+SICOOB!F25+SAFRA!F25+SANTANDER!F42) -> 0 | F7: ='BANCO XP RENATA'!F46+'BANCO ITAÚ RENATA HELIO'!F81+SICOOB!F31+SAFRA!F31+SANTANDER!F52 -> 0 | G7: ='BANCO XP RENATA'!F55+'BANCO ITAÚ RENATA HELIO'!F97+SICOOB!F37+SAFRA!F37+SANTANDER!F62 -> 0 | H7: ='BANCO XP RENATA'!F64+'BANCO ITAÚ RENATA HELIO'!F113+SICOOB!F49+SAFRA!F43+SANTANDER!F72 -> 0 | I7: ='BANCO XP RENATA'!F73+'BANCO ITAÚ RENATA HELIO'!F129+SICOOB!F49+SAFRA!F49+SANTANDER!F82 -> 0 | J7: ='BANCO XP RENATA'!F82+'BANCO ITAÚ RENATA HELIO'!F145+SICOOB!F55+SAFRA!F55+SANTANDER!F92 -> 0 | K7: ='BANCO XP RENATA'!F91+'BANCO ITAÚ RENATA HELIO'!F161+SICOOB!F61+SAFRA!F61+SANTANDER!F102 -> 0 | L7: ='BANCO XP RENATA'!F100+'BANCO ITAÚ RENATA HELIO'!F177+SICOOB!F67+SAFRA!F67+SANTANDER!F112 -> 0 | M7: ='BANCO XP RENATA'!F109+'BANCO ITAÚ RENATA HELIO'!F193+SICOOB!F72+SAFRA!F73+SANTANDER!F122 -> 0
A9: BANCO XP RENATA
B10: 45658 | C10: 45689 | D10: 45717 | E10: 45748 | F10: 45778 | G10: 45809 | H10: 45839 | I10: 45870 | J10: 45901 | K10: 45931 | L10: 45962 | M10: 45992
A11: FUNDO DE INVESTIMENTO | B11: ='BANCO XP RENATA'!H4 -> 587936.23 | C11: ='BANCO XP RENATA'!H13 -> 600266.31 | D11: ='BANCO XP RENATA'!H22 -> 600266.31 | E11: ='BANCO XP RENATA'!H31 -> 600266.31 | F11: ='BANCO XP RENATA'!H40 -> 600266.31 | G11: ='BANCO XP RENATA'!H49 -> 600266.31 | H11: ='BANCO XP RENATA'!H58 -> 600266.31 | I11: ='BANCO XP RENATA'!H67 -> 600266.31 | J11: ='BANCO XP RENATA'!H76 -> 600266.31 | K11: ='BANCO XP RENATA'!H85 -> 600266.31 | L11: ='BANCO XP RENATA'!H94 -> 600266.31 | M11: ='BANCO XP RENATA'!H103 -> 600266.31
A12: RENDA FIXA | B12: ='BANCO XP RENATA'!H5 -> 2745455.6 | C12: ='BANCO XP RENATA'!H14 -> 2768239.4 | D12: ='BANCO XP RENATA'!H23 -> 2768239.4 | E12: ='BANCO XP RENATA'!H32 -> 2768239.4 | F12: ='BANCO XP RENATA'!H41 -> 2768239.4 | G12: ='BANCO XP RENATA'!H50 -> 2768239.4 | H12: ='BANCO XP RENATA'!H59 -> 2768239.4 | I12: ='BANCO XP RENATA'!H68 -> 2768239.4 | J12: ='BANCO XP RENATA'!H77 -> 2768239.4 | K12: ='BANCO XP RENATA'!H86 -> 2768239.4 | L12: ='BANCO XP RENATA'!H95 -> 2768239.4 | M12: ='BANCO XP RENATA'!H104 -> 2768239.4
A13: COE | B13: ='BANCO XP RENATA'!H6 -> 695652.71 | C13: ='BANCO XP RENATA'!H15 -> 698000.33 | D13: ='BANCO XP RENATA'!H24 -> 698000.33 | E13: ='BANCO XP RENATA'!H33 -> 698000.33 | F13: ='BANCO XP RENATA'!H42 -> 698000.33 | G13: ='BANCO XP RENATA'!H51 -> 698000.33 | H13: ='BANCO XP RENATA'!H60 -> 698000.33 | I13: ='BANCO XP RENATA'!H69 -> 698000.33 | J13: ='BANCO XP RENATA'!H78 -> 698000.33 | K13: ='BANCO XP RENATA'!H87 -> 698000.33 | L13: ='BANCO XP RENATA'!H96 -> 698000.33 | M13: ='BANCO XP RENATA'!H105 -> 698000.33
A14: XP 24 HORAS FIRF RL | B14: ='BANCO XP RENATA'!H7 -> 88804.34 | C14: ='BANCO XP RENATA'!H16 -> 89856.51 | D14: ='BANCO XP RENATA'!H25 -> 89856.51 | E14: ='BANCO XP RENATA'!H34 -> 89856.51 | F14: ='BANCO XP RENATA'!H43 -> 89856.51 | G14: ='BANCO XP RENATA'!H52 -> 89856.51 | H14: ='BANCO XP RENATA'!H61 -> 89856.51 | I14: ='BANCO XP RENATA'!H70 -> 89856.51 | J14: ='BANCO XP RENATA'!H79 -> 89856.51 | K14: ='BANCO XP RENATA'!H88 -> 89856.51 | L14: ='BANCO XP RENATA'!H97 -> 89856.51 | M14: ='BANCO XP RENATA'!H106 -> 89856.51
B15: ='BANCO XP RENATA'!H8 -> 0 | C15: ='BANCO XP RENATA'!H17 -> 0 | D15: ='BANCO XP RENATA'!H26 -> 0 | E15: ='BANCO XP RENATA'!H35 -> 0 | F15: ='BANCO XP RENATA'!H44 -> 0 | G15: ='BANCO XP RENATA'!H53 -> 0 | H15: ='BANCO XP RENATA'!H62 -> 0 | I15: ='BANCO XP RENATA'!H71 -> 0 | J15: ='BANCO XP RENATA'!H80 -> 0 | K15: ='BANCO XP RENATA'!H89 -> 0 | L15: ='BANCO XP RENATA'!H98 -> 0 | M15: ='BANCO XP RENATA'!H107 -> 0
B16: ='BANCO XP RENATA'!H9 -> 0 | C16: ='BANCO XP RENATA'!H18 -> 0 | D16: ='BANCO XP RENATA'!H27 -> 0 | E16: ='BANCO XP RENATA'!H36 -> 0 | F16: ='BANCO XP RENATA'!H45 -> 0 | G16: ='BANCO XP RENATA'!H54 -> 0 | H16: ='BANCO XP RENATA'!H63 -> 0 | I16: ='BANCO XP RENATA'!H72 -> 0 | J16: ='BANCO XP RENATA'!H81 -> 0 | K16: ='BANCO XP RENATA'!H90 -> 0 | L16: ='BANCO XP RENATA'!H99 -> 0 | M16: ='BANCO XP RENATA'!H108 -> 0
A17: TOTAL... | B17: =SUM(B11:B16) -> 4117848.9 | C17: =SUM(C11:C16) -> 4156362.5 | D17: =SUM(D11:D16) -> 4156362.5 | E17: =SUM(E11:E16) -> 4156362.5 | F17: =SUM(F11:F16) -> 4156362.5 | G17: =SUM(G11:G16) -> 4156362.5 | H17: =SUM(H11:H16) -> 4156362.5 | I17: =SUM(I11:I16) -> 4156362.5 | ... M17: =SUM(M11:M16) -> 4156362.5
A19: BANCO ITAÚ RENATA
B20: 45658 | C20: 45689 | D20: 45717 | E20: 45748 | F20: 45778 | G20: 45809 | H20: 45839 | I20: 45870 | J20: 45901 | K20: 45931 | L20: 45962 | M20: 45992
A21: Poupança | B21: ='BANCO ITAÚ RENATA HELIO'!H4 -> 1245.19 | C21: ='BANCO ITAÚ RENATA HELIO'!H20 -> 1425.55 | D21: ='BANCO ITAÚ RENATA HELIO'!H36 -> 1425.55 | E21: ='BANCO ITAÚ RENATA HELIO'!H52 -> 1425.55 | F21: ='BANCO ITAÚ RENATA HELIO'!H68 -> 1425.55 | G21: ='BANCO ITAÚ RENATA HELIO'!H84 -> 1425.55 | H21: ='BANCO ITAÚ RENATA HELIO'!H100 -> 1425.55 | I21: ='BANCO ITAÚ RENATA HELIO'!H116 -> 1425.55 | J21: ='BANCO ITAÚ RENATA HELIO'!H132 -> 1425.55 | K21: ='BANCO ITAÚ RENATA HELIO'!H148 -> 1425.55 | L21: ='BANCO ITAÚ RENATA HELIO'!H164 -> 1425.55 | M21: ='BANCO ITAÚ RENATA HELIO'!H180 -> 1425.55
A22: CDB Plus | B22: ='BANCO ITAÚ RENATA HELIO'!H5 -> 691003.88 | C22: ='BANCO ITAÚ RENATA HELIO'!H21 -> 697368.42 | D22: ='BANCO ITAÚ RENATA HELIO'!H37 -> 697368.42 | E22: ='BANCO ITAÚ RENATA HELIO'!H53 -> 697368.42 | F22: ='BANCO ITAÚ RENATA HELIO'!H69 -> 697368.42 | G22: ='BANCO ITAÚ RENATA HELIO'!H85 -> 697368.42 | H22: ='BANCO ITAÚ RENATA HELIO'!H101 -> 697368.42 | I22: ='BANCO ITAÚ RENATA HELIO'!H117 -> 697368.42 | J22: ='BANCO ITAÚ RENATA HELIO'!H133 -> 697368.42 | K22: ='BANCO ITAÚ RENATA HELIO'!H149 -> 697368.42 | L22: ='BANCO ITAÚ RENATA HELIO'!H165 -> 697368.42 | M22: ='BANCO ITAÚ RENATA HELIO'!H181 -> 697368.42
A23: LCADI | B23: ='BANCO ITAÚ RENATA HELIO'!H6 -> 386192.93 | C23: ='BANCO ITAÚ RENATA HELIO'!H22 -> 389907.98 | D23: ='BANCO ITAÚ RENATA HELIO'!H38 -> 389907.98 | E23: ='BANCO ITAÚ RENATA HELIO'!H54 -> 389907.98 | F23: ='BANCO ITAÚ RENATA HELIO'!H70 -> 389907.98 | G23: ='BANCO ITAÚ RENATA HELIO'!H86 -> 389907.98 | H23: ='BANCO ITAÚ RENATA HELIO'!H102 -> 389907.98 | I23: ='BANCO ITAÚ RENATA HELIO'!H118 -> 389907.98 | J23: ='BANCO ITAÚ RENATA HELIO'!H134 -> 389907.98 | K23: ='BANCO ITAÚ RENATA HELIO'!H150 -> 389907.98 | L23: ='BANCO ITAÚ RENATA HELIO'!H166 -> 389907.98 | M23: ='BANCO ITAÚ RENATA HELIO'!H182 -> 389907.98
A24: PIC | B24: ='BANCO ITAÚ RENATA HELIO'!H7 -> 5943.13 | C24: ='BANCO ITAÚ RENATA HELIO'!H23 -> 6446.26 | D24: ='BANCO ITAÚ RENATA HELIO'!H39 -> 6446.26 | E24: ='BANCO ITAÚ RENATA HELIO'!H55 -> 6446.26 | F24: ='BANCO ITAÚ RENATA HELIO'!H71 -> 6446.26 | G24: ='BANCO ITAÚ RENATA HELIO'!H87 -> 6446.26 | H24: ='BANCO ITAÚ RENATA HELIO'!H103 -> 6446.26 | I24: ='BANCO ITAÚ RENATA HELIO'!H119 -> 6446.26 | J24: ='BANCO ITAÚ RENATA HELIO'!H135 -> 6446.26 | K24: ='BANCO ITAÚ RENATA HELIO'!H151 -> 6446.26 | L24: ='BANCO ITAÚ RENATA HELIO'!H167 -> 6446.26 | M24: ='BANCO ITAÚ RENATA HELIO'!H183 -> 6446.26
A25: CDB | B25: ='BANCO ITAÚ RENATA HELIO'!H8 -> 203631.92 | C25: ='BANCO ITAÚ RENATA HELIO'!H24 -> 205490.17 | D25: ='BANCO ITAÚ RENATA HELIO'!H40 -> 205490.17 | E25: ='BANCO ITAÚ RENATA HELIO'!H56 -> 205490.17 | F25: ='BANCO ITAÚ RENATA HELIO'!H72 -> 205490.17 | G25: ='BANCO ITAÚ RENATA HELIO'!H88 -> 205490.17 | H25: ='BANCO ITAÚ RENATA HELIO'!H104 -> 205490.17 | I25: ='BANCO ITAÚ RENATA HELIO'!H120 -> 205490.17 | J25: ='BANCO ITAÚ RENATA HELIO'!H136 -> 205490.17 | K25: ='BANCO ITAÚ RENATA HELIO'!H152 -> 205490.17 | L25: ='BANCO ITAÚ RENATA HELIO'!H168 -> 205490.17 | M25: ='BANCO ITAÚ RENATA HELIO'!H184 -> 205490.17
A26: LCI DI | B26: ='BANCO ITAÚ RENATA HELIO'!H9 -> 238135.85 | C26: ='BANCO ITAÚ RENATA HELIO'!H25 -> 170064.7 | D26: ='BANCO ITAÚ RENATA HELIO'!H41 -> 1970064.7 | E26: ='BANCO ITAÚ RENATA HELIO'!H57 -> 1970064.7 | F26: ='BANCO ITAÚ RENATA HELIO'!H73 -> 1970064.7 | G26: ='BANCO ITAÚ RENATA HELIO'!H89 -> 1970064.7 | H26: ='BANCO ITAÚ RENATA HELIO'!H105 -> 1970064.7 | I26: ='BANCO ITAÚ RENATA HELIO'!H121 -> 1970064.7 | J26: ='BANCO ITAÚ RENATA HELIO'!H137 -> 1970064.7 | K26: ='BANCO ITAÚ RENATA HELIO'!H153 -> 1970064.7 | L26: ='BANCO ITAÚ RENATA HELIO'!H169 -> 1970064.7 | M26: ='BANCO ITAÚ RENATA HELIO'!H185 -> 1970064.7
A27: OPEA SECURITIZADORA | B27: ='BANCO ITAÚ RENATA HELIO'!H10 -> 6772682.3 | C27: ='BANCO ITAÚ RENATA HELIO'!H26 -> 6826823.3 | D27: ='BANCO ITAÚ RENATA HELIO'!H42 -> 5285853.4 | E27: ='BANCO ITAÚ RENATA HELIO'!H58 -> 5285853.4 | F27: ='BANCO ITAÚ RENATA HELIO'!H74 -> 5285853.4 | G27: ='BANCO ITAÚ RENATA HELIO'!H90 -> 5285853.4 | H27: ='BANCO ITAÚ RENATA HELIO'!H106 -> 5285853.4 | I27: ='BANCO ITAÚ RENATA HELIO'!H122 -> 5285853.4 | J27: ='BANCO ITAÚ RENATA HELIO'!H138 -> 5285853.4 | K27: ='BANCO ITAÚ RENATA HELIO'!H154 -> 5285853.4 | L27: ='BANCO ITAÚ RENATA HELIO'!H170 -> 5285853.4 | M27: ='BANCO ITAÚ RENATA HELIO'!H186 -> 5285853.4
A28: CDBDI | B28: ='BANCO ITAÚ RENATA HELIO'!H11 -> 630587.53 | C28: ='BANCO ITAÚ RENATA HELIO'!H27 -> 637993.57 | D28: ='BANCO ITAÚ RENATA HELIO'!H43 -> 637993.57 | E28: ='BANCO ITAÚ RENATA HELIO'!H59 -> 637993.57 | F28: ='BANCO ITAÚ RENATA HELIO'!H75 -> 637993.57 | G28: ='BANCO ITAÚ RENATA HELIO'!H91 -> 637993.57 | H28: ='BANCO ITAÚ RENATA HELIO'!H107 -> 637993.57 | I28: ='BANCO ITAÚ RENATA HELIO'!H123 -> 637993.57 | J28: ='BANCO ITAÚ RENATA HELIO'!H139 -> 637993.57 | K28: ='BANCO ITAÚ RENATA HELIO'!H155 -> 637993.57 | L28: ='BANCO ITAÚ RENATA HELIO'!H171 -> 637993.57 | M28: ='BANCO ITAÚ RENATA HELIO'!H187 -> 637993.57
A29: LCI PRÉ | B29: ='BANCO ITAÚ RENATA HELIO'!H12 -> 85543.64 | C29: ='BANCO ITAÚ RENATA HELIO'!H28 -> 48359.56 | D29: ='BANCO ITAÚ RENATA HELIO'!H44 -> 21958.91 | E29: ='BANCO ITAÚ RENATA HELIO'!H60 -> 21958.91 | F29: ='BANCO ITAÚ RENATA HELIO'!H76 -> 21958.91 | G29: ='BANCO ITAÚ RENATA HELIO'!H92 -> 21958.91 | H29: ='BANCO ITAÚ RENATA HELIO'!H108 -> 21958.91 | I29: ='BANCO ITAÚ RENATA HELIO'!H124 -> 21958.91 | J29: ='BANCO ITAÚ RENATA HELIO'!H140 -> 21958.91 | K29: ='BANCO ITAÚ RENATA HELIO'!H156 -> 21958.91 | L29: ='BANCO ITAÚ RENATA HELIO'!H172 -> 21958.91 | M29: ='BANCO ITAÚ RENATA HELIO'!H188 -> 21958.91
A30: CDB HELIO | B30: ='BANCO ITAÚ RENATA HELIO'!H13 -> 4696.94 | C30: ='BANCO ITAÚ RENATA HELIO'!H29 -> -1.1013412e-13 | D30: ='BANCO ITAÚ RENATA HELIO'!H45 -> -1.1013412e-13 | E30: ='BANCO ITAÚ RENATA HELIO'!H61 -> -1.1013412e-13 | F30: ='BANCO ITAÚ RENATA HELIO'!H77 -> -1.1013412e-13 | G30: ='BANCO ITAÚ RENATA HELIO'!H93 -> -1.1013412e-13 | H30: ='BANCO ITAÚ RENATA HELIO'!H109 -> -1.1013412e-13 | I30: ='BANCO ITAÚ RENATA HELIO'!H125 -> -1.1013412e-13 | J30: ='BANCO ITAÚ RENATA HELIO'!H141 -> -1.1013412e-13 | K30: ='BANCO ITAÚ RENATA HELIO'!H157 -> -1.1013412e-13 | L30: ='BANCO ITAÚ RENATA HELIO'!H173 -> -1.1013412e-13 | M30: ='BANCO ITAÚ RENATA HELIO'!H189 -> -1.1013412e-13
A31: CDB HOLDING | B31: ='BANCO ITAÚ RENATA HELIO'!H14 -> 254847.93 | C31: ='BANCO ITAÚ RENATA HELIO'!H30 -> 251124.69 | D31: ='BANCO ITAÚ RENATA HELIO'!H46 -> 251124.69 | E31: ='BANCO ITAÚ RENATA HELIO'!H62 -> 251124.69 | F31: ='BANCO ITAÚ RENATA HELIO'!H78 -> 251124.69 | G31: ='BANCO ITAÚ RENATA HELIO'!H94 -> 251124.69 | H31: ='BANCO ITAÚ RENATA HELIO'!H110 -> 251124.69 | I31: ='BANCO ITAÚ RENATA HELIO'!H126 -> 251124.69 | J31: ='BANCO ITAÚ RENATA HELIO'!H142 -> 251124.69 | K31: ='BANCO ITAÚ RENATA HELIO'!H158 -> 251124.69 | L31: ='BANCO ITAÚ RENATA HELIO'!H174 -> 251124.69 | M31: ='BANCO ITAÚ RENATA HELIO'!H190 -> 251124.69
A34: TOTAL... | B34: =SUM(B21:B31) -> 9274511.3 | C34: =SUM(C21:C31) -> 9235004.2 | D34: =SUM(D21:D31) -> 9467633.6 | E34: =SUM(E21:E31) -> 9467633.6 | F34: =SUM(F21:F31) -> 9467633.6 | G34: =SUM(G21:G31) -> 9467633.6 | H34: =SUM(H21:H31) -> 9467633.6 | I34: =SUM(I21:I31) -> 9467633.6 | J34: =SUM(J21:J33) -> 9467633.6 | K34: =SUM(K21:K33) -> 9467633.6 | L34: =SUM(L21:L33) -> 9467633.6 | M34: =SUM(M21:M33) -> 9467633.6
A36: BANCO SICOOB CONJUNTA
B37: 45658 | C37: 45689 | D37: 45717 | E37: 45748 | F37: 45778 | G37: 45809 | H37: 45839 | I37: 45870 | J37: 45901 | K37: 45931 | L37: 45962 | M37: 45992
A38: RDC PÓS CDI | B38: =SICOOB!H4 -> 1285909.6 | C38: =SICOOB!H10 -> 1300989.1 | D38: =SICOOB!H16 -> 1300989.1 | E38: =SICOOB!H22 -> 1300989.1 | F38: =SICOOB!H28 -> 1300989.1 | G38: =SICOOB!H34 -> 1300989.1 | H38: =SICOOB!H40 -> 1300989.1 | I38: =SICOOB!H46 -> 1300989.1 | J38: =SICOOB!H52 -> 1300989.1 | K38: =SICOOB!H58 -> 1300989.1 | L38: =SICOOB!H64 -> 1300989.1 | M38: =SICOOB!H69 -> 1300989.1
B39: =SICOOB!H5 -> 0 | C39: =SICOOB!H11 -> 0 | D39: =SICOOB!H17 -> 0 | E39: =SICOOB!H23 -> 0 | F39: =SICOOB!H29 -> 0 | G39: =SICOOB!H35 -> 0 | H39: =SICOOB!H41 -> 0 | I39: =SICOOB!H47 -> 0 | J39: =SICOOB!H53 -> 0 | K39: =SICOOB!H59 -> 0 | L39: =SICOOB!H65 -> 0
B40: =SICOOB!H6 -> 0 | C40: =SICOOB!H12 -> 0 | D40: =SICOOB!H18 -> 0 | E40: =SICOOB!H24 -> 0 | F40: =SICOOB!H30 -> 0 | G40: =SICOOB!H36 -> 0 | H40: =SICOOB!H42 -> 0 | I40: =SICOOB!H48 -> 0 | J40: =SICOOB!H54 -> 0 | K40: =SICOOB!H60 -> 0 | L40: =SICOOB!H66 -> 0 | M40: =SICOOB!H71 -> 0
A41: TOTAL... | B41: =SUM(B38:B40) -> 1285909.6 | C41: =SUM(C38:C40) -> 1300989.1 | D41: =SUM(D38:D40) -> 1300989.1 | E41: =SUM(E38:E40) -> 1300989.1 | F41: =SUM(F38:F40) -> 1300989.1 | G41: =SUM(G38:G40) -> 1300989.1 | H41: =SUM(H38:H40) -> 1300989.1 | I41: =SUM(I38:I40) -> 1300989.1 | ... M41: =SUM(M38:M40) -> 1300989.1
A42: BANCO SAFRA CONJUNTA
B43: 45658 | C43: 45689 | D43: 45717 | E43: 45748 | F43: 45778 | G43: 45809 | H43: 45839 | I43: 45870 | J43: 45901 | K43: 45931 | L43: 45962 | M43: 45992
A44: RDC PÓS CDI | B44: =SAFRA!H4 -> 1389263.2 | C44: =SAFRA!H10 -> 1235751.5 | D44: =SAFRA!H16 -> 894515.45 | E44: =SAFRA!H22 -> 894515.45 | F44: =SAFRA!H28 -> 894515.45 | G44: =SAFRA!H34 -> 894515.45 | H44: =SAFRA!H40 -> 894515.45 | I44: =SAFRA!H46 -> 894515.45 | J44: =SAFRA!H52 -> 894515.45 | K44: =SAFRA!H58 -> 894515.45 | L44: =SAFRA!H64 -> 894515.45 | M44: =SAFRA!H70 -> 894515.45
A45: MULTIMERCADO | B45: =SAFRA!H5 -> 119009.3 | C45: =SAFRA!H11 -> 120446.5 | D45: =SAFRA!H17 -> 61306.78 | E45: =SAFRA!H23 -> 61306.78 | F45: =SAFRA!H29 -> 61306.78 | G45: =SAFRA!H35 -> 61306.78 | H45: =SAFRA!H41 -> 61306.78 | I45: =SAFRA!H47 -> 61306.78 | J45: =SAFRA!H53 -> 61306.78 | K45: =SAFRA!H59 -> 61306.78 | L45: =SAFRA!H65 -> 61306.78 | M45: =SAFRA!H71 -> 61306.78
B46: =SAFRA!H6 -> 0 | C46: =SAFRA!H12 -> 0 | D46: =SAFRA!H18 -> 0 | E46: =SAFRA!H24 -> 0 | F46: =SAFRA!H30 -> 0 | G46: =SAFRA!H36 -> 0 | H46: =SAFRA!H42 -> 0 | I46: =SAFRA!H48 -> 0 | J46: =SAFRA!H54 -> 0 | K46: =SAFRA!H60 -> 0 | L46: =SAFRA!H66 -> 0 | M46: =SAFRA!H72 -> 0
...

Sheet BANCO XP RENATA
A3: 46023 | B3: SALDO ANTERIOR | C3: ENTRADA | D3: SAÍDA | E3: SUB TOTAL | F3: RENDIMENTO $ | G3: RENDIMENTO % | H3: SALDO EM 30/01/2026
A4: FUNDO DE INVESTIMENTO | B4: 586737.13 | E4: =C4+B4-D4 -> 586737.13 | F4: 1199.1 | G4: =F4/B4 -> 0.002043675 | H4: =F4+E4 -> 587936.23
A5: RENDA FIXA | B5: 2744619.8 | D5: 25206.33 | E5: =C5+B5-D5 -> 2719413.4 | F5: 26042.13 | G5: =F5/B5 -> 0.009488429 | H5: =F5+E5 -> 2745455.6
A6: COE | B6: 677006.44 | E6: =C6+B6-D6 -> 677006.44 | F6: 18646.27 | G6: =F6/B6 -> 0.027542234 | H6: =F6+E6 -> 695652.71
A7: XP 24 HORAS FIRF RL | B7: 86892.8 | E7: =C7+B7-D7 -> 86892.8 | F7: 1911.54 | G7: =F7/B7 -> 0.021998831 | H7: =F7+E7 -> 88804.34
E8: =C8+B8-D8 -> 0 | G8: =F8/B8 -> #DIV/0! | H8: =F8+E8 -> 0
E9: =C9+B9-D9 -> 0 | G9: =F9/B9 -> #DIV/0! | H9: =F9+E9 -> 0
A10: TOTAL | B10: =SUM(B4:B9) -> 4095256.1 | F10: =SUM(F4:F9) -> 47799.04 | H10: =SUM(H4:H9) -> 4117848.9
A12: 46054 | B12: SALDO ANTERIOR | C12: ENTRADA | D12: SAÍDA | E12: SUB TOTAL | F12: RENDIMENTO $ | G12: RENDIMENTO % | H12: SALDO EM 30/02/2026
A13: FUNDO DE INVESTIMENTO | B13: =H4 -> 587936.23 | E13: =C13+B13-D13 -> 587936.23 | F13: 12330.08 | G13: =F13/B13 -> 0.020971798 | H13: =F13+E13 -> 600266.31
A14: RENDA FIXA | B14: =H5 -> 2745455.6 | E14: =C14+B14-D14 -> 2745455.6 | F14: 22783.82 | G14: =F14/B14 -> 0.0082987393 | H14: =F14+E14 -> 2768239.4
A15: COE | B15: =H6 -> 695652.71 | E15: =C15+B15-D15 -> 695652.71 | F15: 2347.62 | G15: =F15/B15 -> 0.0033747011 | H15: =F15+E15 -> 698000.33
A16: XP 24 HORAS FIRF RL | B16: =H7 -> 88804.34 | E16: =C16+B16-D16 -> 88804.34 | F16: 1052.17 | G16: =F16/B16 -> 0.011848182 | H16: =F16+E16 -> 89856.51
B17: =H8 -> 0 | E17: =C17+B17-D17 -> 0 | G17: =F17/B17 -> #DIV/0! | H17: =F17+E17 -> 0
B18: =H9 -> 0 | E18: =C18+B18-D18 -> 0 | G18: =F18/B18 -> #DIV/0! | H18: =F18+E18 -> 0
A19: TOTAL | B19: =SUM(B13:B18) -> 4117848.9 | F19: =SUM(F13:F18) -> 38513.69 | H19: =SUM(H13:H18) -> 4156362.5
A21: 46082 | B21: SALDO ANTERIOR | C21: ENTRADA | D21: SAÍDA | E21: SUB TOTAL | F21: RENDIMENTO $ | G21: RENDIMENTO % | H21: SALDO EM 30/03/2026
A22: FUNDO DE INVESTIMENTO | B22: =H13 -> 600266.31 | E22: =C22+B22-D22 -> 600266.31 | G22: =F22/B22 -> 0 | H22: =F22+E22 -> 600266.31
A23: RENDA FIXA | B23: =H14 -> 2768239.4 | E23: =C23+B23-D23 -> 2768239.4 | G23: =F23/B23 -> 0 | H23: =F23+E23 -> 2768239.4
A24: COE | B24: =H15 -> 698000.33 | E24: =C24+B24-D24 -> 698000.33 | G24: =F24/B24 -> 0 | H24: =F24+E24 -> 698000.33
A25: XP 24 HORAS FIRF RL | B25: =H16 -> 89856.51 | E25: =C25+B25-D25 -> 89856.51 | G25: =F26/B26 -> #DIV/0! | H25: =F25+E25 -> 89856.51
B26: =H17 -> 0 | E26: =C26+B26-D26 -> 0 | G26: =F26/B26 -> #DIV/0! | H26: =F26+E26 -> 0
B27: =H18 -> 0 | E27: =C27+B27-D27 -> 0 | G27: =F27/B27 -> #DIV/0! | H27: =F27+E27 -> 0
A28: TOTAL | B28: =SUM(B22:B27) -> 4156362.5 | F28: =SUM(F22:F27) -> 0 | H28: =SUM(H22:H27) -> 4156362.5
A30: 46113 | B30: SALDO ANTERIOR | C30: ENTRADA | D30: SAÍDA | E30: SUB TOTAL | F30: RENDIMENTO $ | G30: RENDIMENTO % | H30: SALDO EM 30/04/2026
A31: FUNDO DE INVESTIMENTO | B31: =H22 -> 600266.31 | E31: =C31+B31-D31 -> 600266.31 | G31: =F31/B31 -> 0 | H31: =F31+E31 -> 600266.31
A32: RENDA FIXA | B32: =H23 -> 2768239.4 | E32: =C32+B32-D32 -> 2768239.4 | G32: =F32/B32 -> 0 | H32: =F32+E32 -> 2768239.4
A33: COE | B33: =H24 -> 698000.33 | E33: =C33+B33-D33 -> 698000.33 | G33: =F33/B33 -> 0 | H33: =F33+E33 -> 698000.33
A34: XP 24 HORAS FIRF RL | B34: =H25 -> 89856.51 | E34: =C34+B34-D34 -> 89856.51 | G34: =F34/B34 -> 0 | H34: =F34+E34 -> 89856.51
B35: =H26 -> 0 | E35: =C35+B35-D35 -> 0 | G35: =F35/B35 -> #DIV/0! | H35: =F35+E35 -> 0
B36: =H27 -> 0 | E36: =C36+B36-D36 -> 0 | G36: =F36/B36 -> #DIV/0! | H36: =F36+E36 -> 0
A37: TOTAL | B37: =SUM(B31:B36) -> 4156362.5 | F37: =SUM(F31:F36) -> 0 | H37: =SUM(H31:H36) -> 4156362.5
A39: 46143 | B39: SALDO ANTERIOR | C39: ENTRADA | D39: SAÍDA | E39: SUB TOTAL | F39: RENDIMENTO $ | G39: RENDIMENTO % | H39: SALDO EM 30/05/2026
A40: FUNDO DE INVESTIMENTO | B40: =H31 -> 600266.31 | E40: =C40+B40-D40 -> 600266.31 | G40: =F40/B40 -> 0 | H40: =F40+E40 -> 600266.31
A41: RENDA FIXA | B41: =H32 -> 2768239.4 | E41: =C41+B41-D41 -> 2768239.4 | G41: =F41/B41 -> 0 | H41: =F41+E41 -> 2768239.4
A42: COE | B42: =H33 -> 698000.33 | E42: =C42+B42-D42 -> 698000.33 | G42: =F42/B42 -> 0 | H42: =F42+E42 -> 698000.33
A43: XP 24 HORAS FIRF RL | B43: =H34 -> 89856.51 | E43: =C43+B43-D43 -> 89856.51 | G43: =F43/B43 -> 0 | H43: =F43+E43 -> 89856.51
B44: =H35 -> 0 | E44: =C44+B44-D44 -> 0 | G44: =F44/B44 -> #DIV/0! | H44: =F44+E44 -> 0
B45: =H36 -> 0 | E45: =C45+B45-D45 -> 0 | G45: =F45/B45 -> #DIV/0! | H45: =F45+E45 -> 0
A46: TOTAL | B46: =SUM(B40:B45) -> 4156362.5 | F46: =SUM(F40:F45) -> 0 | H46: =SUM(H40:H45) -> 4156362.5
...

Sheet BANCO ITAÚ RENATA HELIO
A3: 46023 | B3: SALDO ANTERIOR | C3: ENTRADA | D3: SAÍDA | E3: SUB TOTAL | F3: RENDIMENTO $ | G3: RENDIMENTO % | H3: SALDO EM 30/01/2026
A4: Poupança | B4: 1245.19 | E4: =C4+B4-D4 -> 1245.19 | G4: =F4/B4 -> 0 | H4: =F4+E4 -> 1245.19
A5: CDB Plus | B5: 683661.4 | E5: =C5+B5-D5 -> 683661.4 | F5: 7342.48 | G5: =F5/B5 -> 0.010739936 | H5: =F5+E5 -> 691003.88
A6: LCADI | B6: 381903.41 | E6: =C6+B6-D6 -> 381903.41 | F6: 4289.52 | G6: =F6/B6 -> 0.01123195 | H6: =F6+E6 -> 386192.93
A7: PIC | B7: 5943.13 | E7: =C7+B7-D7 -> 5943.13 | G7: =F7/B7 -> 0 | H7: =F7+E7 -> 5943.13
A8: OPEA SECURITIZADORA | B8: 201239.38 | E8: =C8+B8-D8 -> 201239.38 | F8: 2392.54 | G8: =F8/B8 -> 0.011889025 | H8: =F8+E8 -> 203631.92
A9: CDBDI | B9: 248447.51 | D9: 13000 | E9: =C9+B9-D9 -> 235447.51 | F9: 2688.34 | G9: =F9/B9 -> 0.010820555 | H9: =F9+E9 -> 238135.85
A10: LCI PRÉ | B10: 6712280 | D10: 10000 | E10: =C10+B10-D10 -> 6702280 | F10: 70402.37 | G10: =F10/B10 -> 0.010488593 | H10: =F10+E10 -> 6772682.3
A11: CDB HELIO | B11: 624683.41 | E11: =C11+B11-D11 -> 624683.41 | F11: 5904.12 | G11: =F11/B11 -> 0.0094513795 | H11: =F11+E11 -> 630587.53
A12: CDB HOLDING | B12: 84775.19 | E12: =C12+B12-D12 -> 84775.19 | F12: 768.45 | G12: =F12/B12 -> 0.0090645624 | H12: =F12+E12 -> 85543.64
A13: FUNDOS GLOBAL DINAM RFHOLDING | B13: 4632.28 | E13: =C13+B13-D13 -> 4632.28 | F13: 64.66 | G13: =F13/B13 -> 0.013958569 | H13: =F13+E13 -> 4696.94
A14: FUNDOS TRUST DI HOLDING | B14: 306310.11 | D14: 54000 | E14: =C14+B14-D14 -> 252310.11 | F14: 2537.82 | G14: =F14/B14 -> 0.008285133 | H14: =F14+E14 -> 254847.93
A17: TOTAL | B17: =SUM(B4:B14) -> 9255121 | F17: =SUM(F4:F14) -> 96390.3 | H17: =SUM(H4:H14) -> 9274511.3
A19: 46054 | B19: SALDO ANTERIOR | C19: ENTRADA | D19: SAÍDA | E19: SUB TOTAL | F19: RENDIMENTO $ | G19: RENDIMENTO % | H19: SALDO EM 28/02/2026
A20: Poupança | B20: =H4 -> 1245.19 | E20: =C20+B20-D20 -> 1245.19 | F20: 180.36 | G20: =F20/B20 -> 0.14484536 | H20: =F20+E20 -> 1425.55
A21: CDB Plus | B21: =H5 -> 691003.88 | E21: =C21+B21-D21 -> 691003.88 | F21: 6364.54 | G21: =F21/B21 -> 0.0092105706 | H21: =F21+E21 -> 697368.42
A22: LCADI | B22: =H6 -> 386192.93 | E22: =C22+B22-D22 -> 386192.93 | F22: 3715.05 | G22: =F22/B22 -> 0.0096196738 | H22: =F22+E22 -> 389907.98
A23: PIC | B23: =H7 -> 5943.13 | E23: =C23+B23-D23 -> 5943.13 | F23: 503.13 | G23: =F23/B23 -> 0.084657411 | H23: =F23+E23 -> 6446.26
A24: OPEA SECURITIZADORA | B24: =H8 -> 203631.92 | E24: =C24+B24-D24 -> 203631.92 | F24: 1858.25 | G24: =F24/B24 -> 0.009125534 | H24: =F24+E24 -> 205490.17
A25: CDBDI | B25: =H9 -> 238135.85 | D25: 70000 | E25: =C25+B25-D25 -> 168135.85 | F25: 1928.85 | G25: =F25/B25 -> 0.0080997884 | H25: =F25+E25 -> 170064.7
A26: LCI PRÉ | B26: =H10 -> 6772682.3 | E26: =C26+B26-D26 -> 6772682.3 | F26: 54140.95 | G26: =F26/B26 -> 0.0079940188 | H26: =F26+E26 -> 6826823.3
A27: CDB HELIO | B27: =H11 -> 630587.53 | E27: =C27+B27-D27 -> 630587.53 | F27: 7406.04 | G27: =F27/B27 -> 0.011744666 | H27: =F27+E27 -> 637993.57
A28: CDB HOLDING | B28: =H12 -> 85543.64 | D28: =12000.68+26000.65 -> 38001.33 | E28: =C28+B28-D28 -> 47542.31 | F28: 817.25 | G28: =F28/B28 -> 0.0095536033 | H28: =F28+E28 -> 48359.56
A29: FUNDOS GLOBAL DINAM RFHOLDING | B29: =H13 -> 4696.94 | D29: 4714.07 | E29: =C29+B29-D29 -> -17.13 | F29: 17.13 | G29: =F29/B29 -> 0.0036470553 | H29: =F29+E29 -> -1.1013412e-13
A30: FUNDOS TRUST DI HOLDING | B30: =H14 -> 254847.93 | D30: 6500 | E30: =C30+B30-D30 -> 248347.93 | F30: 2776.76 | G30: =F30/B30 -> 0.010895753 | H30: =F30+E30 -> 251124.69
A33: TOTAL | B33: =SUM(B20:B32) -> 9274511.3 | F33: =SUM(F20:F32) -> 79708.31 | H33: =SUM(H20:H32) -> 9235004.2
A35: 46082 | B35: SALDO ANTERIOR | C35: ENTRADA | D35: SAÍDA | E35: SUB TOTAL | F35: RENDIMENTO $ | G35: RENDIMENTO % | H35: SALDO EM 30/03/2026
A36: Poupança | B36: =H20 -> 1425.55 | E36: =C36+B36-D36 -> 1425.55 | G36: =F36/B36 -> 0 | H36: =F36+E36 -> 1425.55
A37: CDB Plus | B37: =H21 -> 697368.42 | E37: =C37+B37-D37 -> 697368.42 | G37: =F37/B37 -> 0 | H37: =F37+E37 -> 697368.42
A38: LCADI | B38: =H22 -> 389907.98 | E38: =C38+B38-D38 -> 389907.98 | G38: =F38/B38 -> 0 | H38: =F38+E38 -> 389907.98
A39: PIC | B39: =H23 -> 6446.26 | E39: =C39+B39-D39 -> 6446.26 | G39: =F39/B39 -> 0 | H39: =F39+E39 -> 6446.26
A40: OPEA SECURITIZADORA | B40: =H24 -> 205490.17 | E40: =C40+B40-D40 -> 205490.17 | G40: =F40/B40 -> 0 | H40: =F40+E40 -> 205490.17
A41: CDBDI | B41: =H25 -> 170064.7 | C41: 1800000 | E41: =C41+B41-D41 -> 1970064.7 | G41: =F41/B41 -> 0 | H41: =F41+E41 -> 1970064.7
A42: LCI PRÉ | B42: =H26 -> 6826823.3 | D42: 1540969.9 | E42: =C42+B42-D42 -> 5285853.4 | G42: =F42/B42 -> 0 | H42: =F42+E42 -> 5285853.4
A43: CDB HELIO | B43: =H27 -> 637993.57 | E43: =C43+B43-D43 -> 637993.57 | G43: =F43/B43 -> 0 | H43: =F43+E43 -> 637993.57
A44: CDB HOLDING | B44: =H28 -> 48359.56 | D44: 26400.65 | E44: =C44+B44-D44 -> 21958.91 | G44: =F44/B44 -> 0 | H44: =F44+E44 -> 21958.91
A45: FUNDOS GLOBAL DINAM RFHOLDING | B45: =H29 -> -1.1013412e-13 | E45: =C45+B45-D45 -> -1.1013412e-13 | G45: =F45/B45 -> 0 | H45: =F45+E45 -> -1.1013412e-13
A46: FUNDOS TRUST DI HOLDING | B46: =H30 -> 251124.69 | E46: =C46+B46-D46 -> 251124.69 | G46: =F46/B46 -> 0 | H46: =F46+E46 -> 251124.69
A49: TOTAL | B49: =SUM(B36:B48) -> 9235004.2 | F49: =SUM(F36:F48) -> 0 | H49: =SUM(H36:H48) -> 9467633.6
A51: 46113 | B51: SALDO ANTERIOR | C51: ENTRADA | D51: SAÍDA | E51: SUB TOTAL | F51: RENDIMENTO $ | G51: RENDIMENTO % | H51: SALDO EM 30/04/2026
...

Sheet SICOOB
A3: 46023 | B3: SALDO ANTERIOR | C3: ENTRADA | D3: SAÍDA | E3: SUB TOTAL | F3: RENDIMENTO $ | G3: RENDIMENTO % | H3: SALDO EM 30/01/2026
A4: HOLDING | B4: 1271754.7 | E4: =C4+B4-D4 -> 1271754.7 | F4: 14154.87 | G4: =F4/B4 -> 0.011130189 | H4: =F4+E4 -> 1285909.6
E5: =C5+B5-D5 -> 0 | G5: =F5/B5 -> #DIV/0! | H5: =F5+E5 -> 0
E6: =C6+B6-D6 -> 0 | G6: =F6/B6 -> #DIV/0! | H6: =F6+E6 -> 0
A7: TOTAL | B7: =SUM(B4:B6) -> 1271754.7 | C7: =SUM(C4:C6) -> 0 | D7: =SUM(D4:D6) -> 0 | E7: =SUM(E4:E6) -> 1271754.7 | F7: =SUM(F4:F6) -> 14154.87 | G7: =SUM(G4:G6) -> #DIV/0! | H7: =SUM(H4:H6) -> 1285909.6
A9: 46054 | B9: SALDO ANTERIOR | C9: ENTRADA | D9: SAÍDA | E9: SUB TOTAL | F9: RENDIMENTO $ | G9: RENDIMENTO % | H9: SALDO EM 28/02/2026
A10: HPLDING | B10: =H4 -> 1285909.6 | E10: =C10+B10-D10 -> 1285909.6 | F10: 15079.56 | G10: =F10/B10 -> 0.011726766 | H10: =F10+E10 -> 1300989.1
B11: =H5 -> 0 | E11: =C11+B11-D11 -> 0 | G11: =F11/B11 -> #DIV/0! | H11: =F11+E11 -> 0
B12: =H6 -> 0 | E12: =C12+B12-D12 -> 0 | G12: =F12/B12 -> #DIV/0! | H12: =F12+E12 -> 0
A13: TOTAL | B13: =SUM(B10:B12) -> 1285909.6 | C13: =SUM(C10:C12) -> 0 | D13: =SUM(D10:D12) -> 0 | E13: =SUM(E10:E12) -> 1285909.6 | F13: =SUM(F10:F12) -> 15079.56 | G13: =SUM(G10:G12) -> #DIV/0! | H13: =SUM(H10:H12) -> 1300989.1
A15: 46082 | B15: SALDO ANTERIOR | C15: ENTRADA | D15: SAÍDA | E15: SUB TOTAL | F15: RENDIMENTO $ | G15: RENDIMENTO % | H15: 03SALDO EM 30/03/2026
A16: HPLDING | B16: =H10 -> 1300989.1 | E16: =C16+B16-D16 -> 1300989.1 | G16: =F16/B16 -> 0 | H16: =F16+E16 -> 1300989.1
B17: =H11 -> 0 | E17: =C17+B17-D17 -> 0 | G17: =F17/B17 -> #DIV/0! | H17: =F17+E17 -> 0
B18: =H12 -> 0 | E18: =C18+B18-D18 -> 0 | G18: =F18/B18 -> #DIV/0! | H18: =F18+E18 -> 0
A19: TOTAL | B19: =SUM(B16:B18) -> 1300989.1 | C19: =SUM(C16:C18) -> 0 | D19: =SUM(D16:D18) -> 0 | E19: =SUM(E16:E18) -> 1300989.1 | F19: =SUM(F16:F18) -> 0 | G19: =SUM(G16:G18) -> #DIV/0! | H19: =SUM(H16:H18) -> 1300989.1
A21: 46113 | B21: SALDO ANTERIOR | C21: ENTRADA | D21: SAÍDA | E21: SUB TOTAL | F21: RENDIMENTO $ | G21: RENDIMENTO % | H21: SALDO EM 30/04/2026
A22: RDC PÓS CDI | B22: =H16 -> 1300989.1 | E22: =C22+B22-D22 -> 1300989.1 | G22: =F22/B22 -> 0 | H22: =F22+E22 -> 1300989.1
B23: =H17 -> 0 | E23: =C23+B23-D23 -> 0 | G23: =F23/B23 -> #DIV/0! | H23: =F23+E23 -> 0
B24: =H18 -> 0 | E24: =C24+B24-D24 -> 0 | G24: =F24/B24 -> #DIV/0! | H24: =F24+E24 -> 0
A25: TOTAL | B25: =SUM(B22:B24) -> 1300989.1 | C25: =SUM(C22:C24) -> 0 | D25: =SUM(D22:D24) -> 0 | E25: =SUM(E22:E24) -> 1300989.1 | F25: =SUM(F22:F24) -> 0 | G25: =SUM(G22:G24) -> #DIV/0! | H25: =SUM(H22:H24) -> 1300989.1
A27: 46143 | B27: SALDO ANTERIOR | C27: ENTRADA | D27: SAÍDA | E27: SUB TOTAL | F27: RENDIMENTO $ | G27: RENDIMENTO % | H27: SALDO EM 30/05/2026
A28: RDC PÓS CDI | B28: =H22 -> 1300989.1 | E28: =C28+B28-D28 -> 1300989.1 | G28: =F28/B28 -> 0 | H28: =F28+E28 -> 1300989.1
B29: =H23 -> 0 | E29: =C29+B29-D29 -> 0 | G29: =F29/B29 -> #DIV/0! | H29: =F29+E29 -> 0
B30: =H24 -> 0 | E30: =C30+B30-D30 -> 0 | G30: =F30/B30 -> #DIV/0! | H30: =F30+E30 -> 0
A31: TOTAL | B31: =SUM(B28:B30) -> 1300989.1 | C31: =SUM(C28:C30) -> 0 | D31: =SUM(D28:D30) -> 0 | E31: =SUM(E28:E30) -> 1300989.1 | F31: =SUM(F28:F30) -> 0 | G31: =SUM(G28:G30) -> #DIV/0! | H31: =SUM(H28:H30) -> 1300989.1
A33: 46174 | B33: SALDO ANTERIOR | C33: ENTRADA | D33: SAÍDA | E33: SUB TOTAL | F33: RENDIMENTO $ | G33: RENDIMENTO % | H33: SALDO EM 30/06/2026
A34: RDC PÓS CDI | B34: =H28 -> 1300989.1 | E34: =C34+B34-D34 -> 1300989.1 | G34: =F34/B34 -> 0 | H34: =F34+E34 -> 1300989.1
B35: =H29 -> 0 | E35: =C35+B35-D35 -> 0 | G35: =F35/B35 -> #DIV/0! | H35: =F35+E35 -> 0
B36: =H30 -> 0 | E36: =C36+B36-D36 -> 0 | G36: =F36/B36 -> #DIV/0! | H36: =F36+E36 -> 0
A37: TOTAL | B37: =SUM(B34:B36) -> 1300989.1 | C37: =SUM(C34:C36) -> 0 | D37: =SUM(D34:D36) -> 0 | E37: =SUM(E34:E36) -> 1300989.1 | F37: =SUM(F34:F36) -> 0 | G37: =SUM(G34:G36) -> #DIV/0! | H37: =SUM(H34:H36) -> 1300989.1
A39: 46204 | B39: SALDO ANTERIOR | C39: ENTRADA | D39: SAÍDA | E39: SUB TOTAL | F39: RENDIMENTO $ | G39: RENDIMENTO % | H39: SALDO EM 30/07/2026
A40: RDC PÓS CDI | B40: =H34 -> 1300989.1 | E40: =C40+B40-D40 -> 1300989.1 | G40: =F40/B40 -> 0 | H40: =F40+E40 -> 1300989.1
A41: HOLDING | B41: =H35 -> 0 | E41: =C41+B41-D41 -> 0 | G41: =F41/B41 -> #DIV/0! | H41: =F41+E41 -> 0
B42: =H36 -> 0 | E42: =C42+B42-D42 -> 0 | G42: =F42/B42 -> #DIV/0! | H42: =F42+E42 -> 0
A43: TOTAL | B43: =SUM(B40:B42) -> 1300989.1 | C43: =SUM(C40:C42) -> 0 | D43: =SUM(D40:D42) -> 0 | E43: =SUM(E40:E42) -> 1300989.1 | F43: =SUM(F40:F42) -> 0 | G43: =SUM(G40:G42) -> #DIV/0! | H43: =SUM(H40:H42) -> 1300989.1
A45: 46235 | B45: SALDO ANTERIOR | C45: ENTRADA | D45: SAÍDA | E45: SUB TOTAL | F45: RENDIMENTO $ | G45: RENDIMENTO % | H45: SALDO EM 30/08/2026
A46: RDC PÓS CDI | B46: =H40 -> 1300989.1 | E46: =C46+B46-D46 -> 1300989.1 | G46: =F46/B46 -> 0 | H46: =F46+E46 -> 1300989.1
A47: HOLDING | B47: =H41 -> 0 | E47: =C47+B47-D47 -> 0 | G47: =F47/B47 -> #DIV/0! | H47: =F47+E47 -> 0
B48: =H42 -> 0 | E48: =C48+B48-D48 -> 0 | G48: =F48/B48 -> #DIV/0! | H48: =F48+E48 -> 0
A49: TOTAL | B49: =SUM(B46:B48) -> 1300989.1 | C49: =SUM(C46:C48) -> 0 | D49: =SUM(D46:D48) -> 0 | E49: =SUM(E46:E48) -> 1300989.1 | F49: =SUM(F46:F48) -> 0 | G49: =SUM(G46:G48) -> #DIV/0! | H49: =SUM(H46:H48) -> 1300989.1
...

Sheet SAFRA
A3: 46023 | B3: SALDO ANTERIOR | C3: ENTRADA | D3: SAÍDA | E3: SUB TOTAL | F3: RENDIMENTO $ | G3: RENDIMENTO % | H3: 46052
A4: CDI | B4: 1400531.1 | D4: 30255.04 | E4: =C4+B4-D4 -> 1370276.1 | F4: 18987.14 | G4: =IFERROR(F4/B4,0) -> 0.0135571 | H4: =F4+E4 -> 1389263.2
A5: MULTIMERCADO | B5: 117520.94 | E5: =C5+B5-D5 -> 117520.94 | F5: 1488.36 | G5: =IFERROR(F5/B5,0) -> 0.012664637 | H5: =F5+E5 -> 119009.3
E6: =C6+B6-D6 -> 0 | G6: =IFERROR(F6/B6,0) -> 0 | H6: =F6+E6 -> 0
A7: TOTAL | B7: =SUM(B4:B6) -> 1518052 | C7: =SUM(C4:C6) -> 0 | D7: =SUM(D4:D6) -> 30255.04 | E7: =SUM(E4:E6) -> 1487797 | F7: =SUM(F4:F6) -> 20475.5 | G7: =AVERAGE(G4:G5) -> 0.013110868 | H7: =SUM(H4:H6) -> 1508272.5
A9: 46054 | B9: SALDO ANTERIOR | C9: ENTRADA | D9: SAÍDA | E9: SUB TOTAL | F9: RENDIMENTO $ | G9: RENDIMENTO % | H9: 46081
A10: CDI | B10: =H4 -> 1389263.2 | D10: =20000+132000+12000 -> 164000 | E10: =C10+B10-D10 -> 1225263.2 | F10: 10488.27 | G10: =IFERROR(F10/B10,0) -> 0.0075495198 | H10: =F10+E10 -> 1235751.5
A11: MULTIMERCADO | B11: =H5 -> 119009.3 | E11: =C11+B11-D11 -> 119009.3 | F11: 1437.2 | G11: =IFERROR(F11/B11,0) -> 0.012076367 | H11: =F11+E11 -> 120446.5
B12: =H6 -> 0 | E12: =C12+B12-D12 -> 0 | G12: =IFERROR(F12/B12,0) -> 0 | H12: =F12+E12 -> 0
A13: TOTAL | B13: =SUM(B10:B12) -> 1508272.5 | C13: =SUM(C10:C12) -> 0 | D13: =SUM(D10:D12) -> 164000 | E13: =SUM(E10:E12) -> 1344272.5 | F13: =SUM(F10:F12) -> 11925.47 | G13: =AVERAGE(G10:G11) -> 0.0098129435 | H13: =SUM(H10:H12) -> 1356198
A15: 46082 | B15: SALDO ANTERIOR | C15: ENTRADA | D15: SAÍDA | E15: SUB TOTAL | F15: RENDIMENTO $ | G15: RENDIMENTO % | H15: 46111
A16: CDI | B16: =H10 -> 1235751.5 | D16: 341236.02 | E16: =C16+B16-D16 -> 894515.45 | G16: =IFERROR(F16/B16,0) -> 0 | H16: =F16+E16 -> 894515.45
A17: MULTIMERCADO | B17: =H11 -> 120446.5 | D17: 59139.72 | E17: =C17+B17-D17 -> 61306.78 | G17: =IFERROR(F17/B17,0) -> 0 | H17: =F17+E17 -> 61306.78
B18: =H12 -> 0 | E18: =C18+B18-D18 -> 0 | G18: =IFERROR(F18/B18,0) -> 0 | H18: =F18+E18 -> 0
A19: TOTAL | B19: =SUM(B16:B18) -> 1356198 | C19: =SUM(C16:C18) -> 0 | D19: =SUM(D16:D18) -> 400375.74 | E19: =SUM(E16:E18) -> 955822.23 | F19: =SUM(F16:F18) -> 0 | G19: =SUM(G16:G18) -> 0 | H19: =SUM(H16:H18) -> 955822.23
A21: 46113 | B21: SALDO ANTERIOR | C21: ENTRADA | D21: SAÍDA | E21: SUB TOTAL | F21: RENDIMENTO $ | G21: RENDIMENTO % | H21: 46142
A22: CDI | B22: =H16 -> 894515.45 | E22: =C22+B22-D22 -> 894515.45 | G22: =IFERROR(F22/B22,0) -> 0 | H22: =F22+E22 -> 894515.45
A23: MULTIMERCADO | B23: =H17 -> 61306.78 | E23: =C23+B23-D23 -> 61306.78 | G23: =IFERROR(F23/B23,0) -> 0 | H23: =F23+E23 -> 61306.78
B24: =H18 -> 0 | E24: =C24+B24-D24 -> 0 | G24: =IFERROR(F24/B24,0) -> 0 | H24: =F24+E24 -> 0
A25: TOTAL | B25: =SUM(B22:B24) -> 955822.23 | C25: =SUM(C22:C24) -> 0 | D25: =SUM(D22:D24) -> 0 | E25: =SUM(E22:E24) -> 955822.23 | F25: =SUM(F22:F24) -> 0 | G25: =SUM(G22:G24) -> 0 | H25: =SUM(H22:H24) -> 955822.23
A27: 46143 | B27: SALDO ANTERIOR | C27: ENTRADA | D27: SAÍDA | E27: SUB TOTAL | F27: RENDIMENTO $ | G27: RENDIMENTO % | H27: 46172
A28: RENDA FIXA | B28: =H22 -> 894515.45 | E28: =C28+B28-D28 -> 894515.45 | G28: =IFERROR(F28/B28,0) -> 0 | H28: =F28+E28 -> 894515.45
A29: MULTIMERCADO | B29: =H23 -> 61306.78 | E29: =C29+B29-D29 -> 61306.78 | G29: =IFERROR(F29/B29,0) -> 0 | H29: =F29+E29 -> 61306.78
B30: =H24 -> 0 | E30: =C30+B30-D30 -> 0 | G30: =IFERROR(F30/B30,0) -> 0 | H30: =F30+E30 -> 0
A31: TOTAL | B31: =SUM(B28:B30) -> 955822.23 | C31: =SUM(C28:C30) -> 0 | D31: =SUM(D28:D30) -> 0 | E31: =SUM(E28:E30) -> 955822.23 | F31: =SUM(F28:F30) -> 0 | G31: =SUM(G28:G30) -> 0 | H31: =SUM(H28:H30) -> 955822.23
A33: 46174 | B33: SALDO ANTERIOR | C33: ENTRADA | D33: SAÍDA | E33: SUB TOTAL | F33: RENDIMENTO $ | G33: RENDIMENTO % | H33: 46203
A34: CDI | B34: =H28 -> 894515.45 | E34: =C34+B34-D34 -> 894515.45 | G34: =IFERROR(F34/B34,0) -> 0 | H34: =F34+E34 -> 894515.45
A35: MULTIMERCADO | B35: =H29 -> 61306.78 | E35: =C35+B35-D35 -> 61306.78 | G35: =IFERROR(F35/B35,0) -> 0 | H35: =F35+E35 -> 61306.78
B36: =H30 -> 0 | E36: =C36+B36-D36 -> 0 | G36: =IFERROR(F36/B36,0) -> 0 | H36: =F36+E36 -> 0
A37: TOTAL | B37: =SUM(B34:B36) -> 955822.23 | C37: =SUM(C34:C36) -> 0 | D37: =SUM(D34:D36) -> 0 | E37: =SUM(E34:E36) -> 955822.23 | F37: =SUM(F34:F36) -> 0 | G37: =SUM(G34:G36) -> 0 | H37: =SUM(H34:H36) -> 955822.23
A39: 46204 | B39: SALDO ANTERIOR | C39: ENTRADA | D39: SAÍDA | E39: SUB TOTAL | F39: RENDIMENTO $ | G39: RENDIMENTO % | H39: 46233
A40: CDI | B40: =H34 -> 894515.45 | E40: =C40+B40-D40 -> 894515.45 | G40: =IFERROR(F40/B40,0) -> 0 | H40: =F40+E40 -> 894515.45
A41: MULTIMERCADO | B41: =H35 -> 61306.78 | E41: =C41+B41-D41 -> 61306.78 | G41: =IFERROR(F41/B41,0) -> 0 | H41: =F41+E41 -> 61306.78
B42: =H36 -> 0 | E42: =C42+B42-D42 -> 0 | G42: =IFERROR(F42/B42,0) -> 0 | H42: =F42+E42 -> 0
A43: TOTAL | B43: =SUM(B40:B42) -> 955822.23 | C43: =SUM(C40:C42) -> 0 | D43: =SUM(D40:D42) -> 0 | E43: =SUM(E40:E42) -> 955822.23 | F43: =SUM(F40:F42) -> 0 | G43: =SUM(G40:G42) -> 0 | H43: =SUM(H40:H42) -> 955822.23
A45: 46235 | B45: SALDO ANTERIOR | C45: ENTRADA | D45: SAÍDA | E45: SUB TOTAL | F45: RENDIMENTO $ | G45: RENDIMENTO % | H45: 46264
A46: CDI | B46: =H40 -> 894515.45 | E46: =C46+B46-D46 -> 894515.45 | G46: =IFERROR(F46/B46,0) -> 0 | H46: =F46+E46 -> 894515.45
A47: MULTIMERCADO | B47: =H41 -> 61306.78 | E47: =C47+B47-D47 -> 61306.78 | G47: =IFERROR(F47/B47,0) -> 0 | H47: =F47+E47 -> 61306.78
B48: =H42 -> 0 | E48: =C48+B48-D48 -> 0 | G48: =IFERROR(F48/B48,0) -> 0 | H48: =F48+E48 -> 0
A49: TOTAL | B49: =SUM(B46:B48) -> 955822.23 | C49: =SUM(C46:C48) -> 0 | D49: =SUM(D46:D48) -> 0 | E49: =SUM(E46:E48) -> 955822.23 | F49: =SUM(F46:F48) -> 0 | G49: =SUM(G46:G48) -> 0 | H49: =SUM(H46:H48) -> 955822.23
...

Sheet SANTANDER
A4: 46023 | B4: SALDO ANTERIOR | C4: ENTRADA | D4: SAÍDA | E4: SUB TOTAL | F4: RENDIMENTO $ | G4: RENDIMENTO % | H4: SALDO EM 30/01/26
A5: FUNDOS | B5: 2728580.6 | D5: 60000 | E5: =B5+C5-D5 -> 2668580.6 | F5: 76766.05 | G5: =IFERROR(F5/B5,0) -> 0.02813406 | H5: =F5+E5 -> 2745346.6
A6: CRÉDITO PRIVADO | B6: 264083.98 | E6: =B6+C6-D6 -> 264083.98 | F6: 2566.7 | G6: =IFERROR(F6/B6,0) -> 0.0097192567 | H6: =F6+E6 -> 266650.68
A7: TÍTULOS PÚBLICOS | B7: 446881.84 | E7: =B7+C7-D7 -> 446881.84 | F7: 2964.81 | G7: =IFERROR(F7/B7,0) -> 0.0066344383 | H7: =F7+E7 -> 449846.65
A8: PREVIDENCIA | B8: 934267.54 | E8: =B8+C8-D8 -> 934267.54 | F8: 5869.37 | G8: =IFERROR(F8/B8,0) -> 0.0062823225 | H8: =F8+E8 -> 940136.91
A9: LCADI | B9: 354270.06 | E9: =B9+C9-D9 -> 354270.06 | F9: 3792.64 | G9: =IFERROR(F9/B9,0) -> 0.010705505 | H9: =F9+E9 -> 358062.7
A10: HELIO | B10: 22606.48 | E10: =B10+C10-D10 -> 22606.48 | F10: 205.59 | G10: =IFERROR(F10/B10,0) -> 0.0090942951 | H10: =F10+E10 -> 22812.07
G11: =IFERROR(F11/B11,0) -> 0 | H11: =F11+E11 -> 0
A12: TOTAL | B12: =SUM(B5:B11) -> 4750690.5 | C12: =SUM(C5:C11) -> 0 | D12: =SUM(D5:D11) -> 60000 | E12: =SUM(E5:E11) -> 4690690.5 | F12: =SUM(F5:F11) -> 92165.16 | G12: =SUM(G5:G11) -> 0.070569878 | H12: =SUM(H5:H11) -> 4782855.6
A14: 46054 | B14: SALDO ANTERIOR | C14: ENTRADA | D14: SAÍDA | E14: SUB TOTAL | F14: RENDIMENTO $ | G14: RENDIMENTO % | H14: SALDO EM 28/02/26
A15: FUNDOS | B15: =H5 -> 2745346.6 | E15: =B15+C15-D15 -> 2745346.6 | F15: 577.19 | G15: =IFERROR(F15/B15,0) -> 0.00021024303 | H15: =F15+E15 -> 2745923.8
A16: CRÉDITO PRIVADO | B16: =H6 -> 266650.68 | E16: =B16+C16-D16 -> 266650.68 | F16: 2525.73 | G16: =IFERROR(F16/B16,0) -> 0.0094720553 | H16: =F16+E16 -> 269176.41
A17: TÍTULOS PÚBLICOS | B17: =H7 -> 449846.65 | D17: 10658.87 | E17: =B17+C17-D17 -> 439187.78 | F17: 3130.2 | G17: =IFERROR(F17/B17,0) -> 0.0069583713 | H17: =F17+E17 -> 442317.98
A18: PREVIDENCIA | B18: =H8 -> 940136.91 | E18: =B18+C18-D18 -> 940136.91 | F18: 4975.06 | G18: =IFERROR(F18/B18,0) -> 0.0052918463 | H18: =F18+E18 -> 945111.97
A19: LCADI | B19: =H9 -> 358062.7 | E19: =B19+C19-D19 -> 358062.7 | F19: 3283.14 | G19: =IFERROR(F19/AM58,0) -> 0 | H19: =F19+E19 -> 361345.84
A20: HELIO | B20: =H10 -> 22812.07 | E20: =B20+C20-D20 -> 22812.07 | F20: 572.83 | G20: =IFERROR(F20/B20,0) -> 0.025110829 | H20: =F20+E20 -> 23384.9
B21: =H11 -> 0 | G21: =IFERROR(F21/B21,0) -> 0 | H21: =F21+E21 -> 0
A22: TOTAL | B22: =SUM(B15:B21) -> 4782855.6 | C22: =SUM(C15:C21) -> 0 | D22: =SUM(D15:D21) -> 10658.87 | E22: =SUM(E15:E21) -> 4772196.8 | F22: =SUM(F15:F21) -> 15064.15 | G22: =SUM(G15:G21) -> 0.047043345 | H22: =SUM(H15:H21) -> 4787260.9
A24: 46082 | B24: SALDO ANTERIOR | C24: ENTRADA | D24: SAÍDA | E24: SUB TOTAL | F24: RENDIMENTO $ | G24: RENDIMENTO % | H24: SALDO EM 30/03/26
A25: FUNDOS | B25: =H15 -> 2745923.8 | E25: =B25+C25-D25 -> 2745923.8 | G25: =IFERROR(F25/B25,0) -> 0 | H25: =F25+E25 -> 2745923.8
A26: CRÉDITO PRIVADO | B26: =H16 -> 269176.41 | E26: =B26+C26-D26 -> 269176.41 | G26: =IFERROR(F26/B26,0) -> 0 | H26: =F26+E26 -> 269176.41
A27: TÍTULOS PÚBLICOS | B27: =H17 -> 442317.98 | E27: =B27+C27-D27 -> 442317.98 | G27: =IFERROR(F27/B27,0) -> 0 | H27: =F27+E27 -> 442317.98
A28: PREVIDENCIA | B28: =H18 -> 945111.97 | E28: =B28+C28-D28 -> 945111.97 | G28: =IFERROR(F28/B28,0) -> 0 | H28: =F28+E28 -> 945111.97
A29: LCADI | B29: =H19 -> 361345.84 | E29: =B29+C29-D29 -> 361345.84 | G29: =IFERROR(F29/B29,0) -> 0 | H29: =F29+E29 -> 361345.84
A30: HELIO | B30: =H20 -> 23384.9 | E30: =B30+C30-D30 -> 23384.9 | G30: =IFERROR(F30/B30,0) -> 0 | H30: =F30+E30 -> 23384.9
B31: =H21 -> 0 | G31: =IFERROR(F31/B31,0) -> 0 | H31: =F31+E31 -> 0
A32: TOTAL | B32: =SUM(B25:B31) -> 4787260.9 | C32: =SUM(C26:C31) -> 0 | D32: =SUM(D26:D31) -> 0 | E32: =SUM(E25:E31) -> 4787260.9 | F32: =SUM(F26:F31) -> 0 | G32: =SUM(G26:G31) -> 0 | H32: =SUM(H25:H31) -> 4787260.9
A34: 46113 | B34: SALDO ANTERIOR | C34: ENTRADA | D34: SAÍDA | E34: SUB TOTAL | F34: RENDIMENTO $ | G34: RENDIMENTO % | H34: SALDO EM 28/04/26
A35: FUNDOS | B35: =H25 -> 2745923.8 | E35: =B35+C35-D35 -> 2745923.8 | G35: =IFERROR(F35/B35,0) -> 0 | H35: =F35+E35 -> 2745923.8
A36: CRÉDITO PRIVADO | B36: =H26 -> 269176.41 | E36: =B36+C36-D36 -> 269176.41 | G36: =IFERROR(F36/B36,0) -> 0 | H36: =F36+E36 -> 269176.41
A37: TÍTULOS PÚBLICOS | B37: =H27 -> 442317.98 | E37: =B37+C37-D37 -> 442317.98 | G37: =IFERROR(F37/B37,0) -> 0 | H37: =F37+E37 -> 442317.98
A38: PREVIDENCIA | B38: =H28 -> 945111.97 | E38: =B38+C38-D38 -> 945111.97 | G38: =IFERROR(F38/B38,0) -> 0 | H38: =F38+E38 -> 945111.97
A39: LCADI | B39: =H29 -> 361345.84 | E39: =B39+C39-D39 -> 361345.84 | G39: =IFERROR(F39/B39,0) -> 0 | H39: =F39+E39 -> 361345.84
A40: HELIO | B40: =H30 -> 23384.9 | E40: =B40+C40-D40 -> 23384.9 | G40: =IFERROR(F40/B40,0) -> 0 | H40: =F40+E40 -> 23384.9
B41: =H31 -> 0 | G41: =IFERROR(F41/B41,0) -> 0 | H41: =F41+E41 -> 0
A42: TOTAL | B42: =SUM(B35:B41) -> 4787260.9 | C42: =SUM(C35:C41) -> 0 | D42: =SUM(D35:D41) -> 0 | E42: =SUM(E35:E41) -> 4787260.9 | F42: =SUM(F35:F41) -> 0 | G42: =SUM(G35:G41) -> 0 | H42: =SUM(H35:H41) -> 4787260.9
A44: 46143 | B44: SALDO ANTERIOR | C44: ENTRADA | D44: SAÍDA | E44: SUB TOTAL | F44: RENDIMENTO $ | G44: RENDIMENTO % | H44: SALDO EM 30/05/26
A45: FUNDOS | B45: =H35 -> 2745923.8 | E45: =B45+C45-D45 -> 2745923.8 | G45: =IFERROR(F45/B45,0) -> 0 | H45: =F45+E45 -> 2745923.8
A46: CRÉDITO PRIVADO | B46: =H36 -> 269176.41 | E46: =B46+C46-D46 -> 269176.41 | G46: =IFERROR(F46/B46,0) -> 0 | H46: =F46+E46 -> 269176.41
A47: TÍTULOS PÚBLICOS | B47: =H37 -> 442317.98 | E47: =B47+C47-D47 -> 442317.98 | G47: =IFERROR(F47/B47,0) -> 0 | H47: =F47+E47 -> 442317.98
...
